2017-09-12 22:49:01,998 root     CRITICAL Application generated an exception during startup and will now terminate. Exception:
 Traceback (most recent call last):
  File "/share/LocalPythonTools/src/morne/sdk/app/Application.py", line 124, in start
    self.on_start()
  File "CRUDTest.py", line 118, in on_start
    self.PERF_SQL_TOTAL_ROW_COUNT.set_initial_value(conn.test_db.test_table.count())
  File "/morne/local/lib/python2.7/site-packages/pymongo/collection.py", line 1394, in count
    return self._count(cmd, collation)
  File "/morne/local/lib/python2.7/site-packages/pymongo/collection.py", line 1344, in _count
    with self._socket_for_reads() as (sock_info, slave_ok):
  File "/usr/lib/python2.7/contextlib.py", line 17, in __enter__
    return self.gen.next()
  File "/morne/local/lib/python2.7/site-packages/pymongo/mongo_client.py", line 904, in _socket_for_reads
    with self._get_socket(read_preference) as sock_info:
  File "/usr/lib/python2.7/contextlib.py", line 17, in __enter__
    return self.gen.next()
  File "/morne/local/lib/python2.7/site-packages/pymongo/mongo_client.py", line 868, in _get_socket
    server = self._get_topology().select_server(selector)
  File "/morne/local/lib/python2.7/site-packages/pymongo/topology.py", line 214, in select_server
    address))
  File "/morne/local/lib/python2.7/site-packages/pymongo/topology.py", line 189, in select_servers
    self._error_message(selector))
ServerSelectionTimeoutError: 10.0.0.50:27017: [Errno 111] Connection refused

